<?xml version="1.0" ?>
<sdf version="1.8">
        <physics name="1ms" type="ode">
            <max_step_size>0.001</max_step_size>
            <real_time_factor>1.0</real_time_factor>
        </physics>

        <plugin filename="gz-sim-physics-system" name="gz::sim::systems::Physics"/>
        <plugin filename="gz-sim-user-commands-system" name="gz::sim::systems::UserCommands"/>
        <plugin filename="gz-sim-scene-broadcaster-system" name="gz::sim::systems::SceneBroadcaster"/>
        <plugin filename="gz-sim-imu-system" name="gz::sim::systems::Imu"/>
        <plugin filename="gz-sim-sensors-system" name="gz::sim::systems::Sensors">
            <render_engine>ogre2</render_engine>
        </plugin>
        <plugin filename="gz-sim-contact-system" name="gz::sim::systems::Contact"/>

        <model name='pan_tilt_system' canonical_link='base'>

            <link name='base'>
                <pose relative_to='__model__'>0 0 -1.0 0 0 1.5708</pose>
                <inertial>
                    <mass>50</mass>
                    <inertia>
                        <ixx>0.729165</ixx>
                        <ixy>0</ixy>
                        <ixz>0</ixz>
                        <iyy>0.729165</iyy>
                        <iyz>0</iyz>
                        <izz>0.625</izz>
                    </inertia>
                </inertial>
                <visual name='visual'>
                    <pose>0 0 0 0 0 0</pose>
                    <geometry>
                        <mesh>
                            <uri>file:///home/kimsh/ros2_ws/src/pan_tilt/sdf/meshes/base.dae</uri>
                            <scale>0.01 0.01 0.01</scale>
                        </mesh>
                    </geometry>
                </visual>
                <collision name="collision">
                    <geometry>
                        <mesh>
                            <uri>file:///home/kimsh/ros2_ws/src/pan_tilt/sdf/meshes/base.dae</uri>
                            <scale>0.01 0.01 0.01</scale>
                        </mesh>
                    </geometry>
                </collision>
            </link>
            
            <link name='pan_motor'>
                <pose relative_to='base'>0 0 0.34 1.5708 0 0</pose>
                <inertial>
                    <mass>5</mass>
                    <inertia>
                        <ixx>0.145833</ixx>
                        <ixy>0</ixy>
                        <ixz>0</ixz>
                        <iyy>0.145833</iyy>
                        <iyz>0</iyz>
                        <izz>0.125</izz>
                    </inertia>
                </inertial>
                <visual name='visual'>
                    <pose>0 0 0 0 0 0</pose>
                    <geometry>
                        <mesh>
                            <uri>file:///home/kimsh/ros2_ws/src/pan_tilt/sdf/meshes/ym080.dae</uri>
                            <scale>0.01 0.01 0.01</scale>
                        </mesh>
                    </geometry>
                </visual>
                <collision name="collision">
                    <geometry>
                        <mesh>
                            <uri>file:///home/kimsh/ros2_ws/src/pan_tilt/sdf/meshes/ym080.dae</uri>
                            <scale>0.01 0.01 0.01</scale>
                        </mesh>
                    </geometry>
                </collision>
            </link>
            
            <link name='pan_support'>
                <pose relative_to='pan_motor'>0.31 0.035 0 -1.5708 -1.5708 0</pose>
                <inertial>
                    <mass>5</mass>
                    <inertia>
                        <ixx>0.145833</ixx>
                        <ixy>0</ixy>
                        <ixz>0</ixz>
                        <iyy>0.145833</iyy>
                        <iyz>0</iyz>
                        <izz>0.125</izz>
                    </inertia>
                </inertial>
                <visual name='visual'>
                    <pose>0 0 0 0 0 0</pose>
                    <geometry>
                        <mesh>
                            <uri>file:///home/kimsh/ros2_ws/src/pan_tilt/sdf/meshes/pan_support.dae</uri>
                            <scale>0.01 0.01 0.01</scale>
                        </mesh>
                    </geometry>
                </visual>
                <collision name="collision">
                    <geometry>
                        <mesh>
                            <uri>file:///home/kimsh/ros2_ws/src/pan_tilt/sdf/meshes/pan_support.dae</uri>
                            <scale>0.01 0.01 0.01</scale>
                        </mesh>
                    </geometry>
                </collision>
            </link>
            
            <link name='tilt_motor'>
                <pose relative_to='pan_support'>0 0.02 0.232 3.14159 0 0</pose>
                <inertial>
                    <mass>5</mass>
                    <inertia>
                        <ixx>0.145833</ixx>
                        <ixy>0</ixy>
                        <ixz>0</ixz>
                        <iyy>0.145833</iyy>
                        <iyz>0</iyz>
                        <izz>0.125</izz>
                    </inertia>
                </inertial>
                <visual name='visual'>
                    <pose>0 0 0 0 0 0</pose>
                    <geometry>
                        <mesh>
                            <uri>file:///home/kimsh/ros2_ws/src/pan_tilt/sdf/meshes/ym080.dae</uri>
                            <scale>0.01 0.01 0.01</scale>
                        </mesh>
                    </geometry>
                </visual>
                <collision name="collision">
                    <geometry>
                        <mesh>
                            <uri>file:///home/kimsh/ros2_ws/src/pan_tilt/sdf/meshes/ym080.dae</uri>
                            <scale>0.01 0.01 0.01</scale>
                        </mesh>
                    </geometry>
                </collision>
            </link>
            
            <link name='plate'>
                <pose relative_to='tilt_motor'>0 0.34 0.01 3.14159 0 1.5708</pose>
                <inertial>
                    <mass>1</mass>
                    <inertia>
                        <ixx>0.145833</ixx>
                        <ixy>0</ixy>
                        <ixz>0</ixz>
                        <iyy>0.145833</iyy>
                        <iyz>0</iyz>
                        <izz>0.125</izz>
                    </inertia>
                </inertial>
                <visual name='visual'>
                    <pose>0 0 0 0 0 0</pose>
                    <geometry>
                        <mesh>
                            <uri>file:///home/kimsh/ros2_ws/src/pan_tilt/sdf/meshes/plate.dae</uri>
                            <scale>0.01 0.01 0.01</scale>
                        </mesh>
                    </geometry>
                </visual>
                <collision name="collision">
                    <geometry>
                        <mesh>
                            <uri>file:///home/kimsh/ros2_ws/src/pan_tilt/sdf/meshes/plate.dae</uri>
                            <scale>0.01 0.01 0.01</scale>
                        </mesh>
                    </geometry>
                </collision>
            </link>
            
            <joint name='base_joint' type='revolute'>
                <parent>base</parent>
                <child>pan_motor</child>
                <axis>
                    <xyz>0 1 0</xyz>
                    <limit>
                        <lower>-1e16</lower>
                        <upper>1e16</upper>
                        <effort>5e6</effort>
                    </limit>
                </axis>
            </joint>
            
            <joint name='pan_motor_joint' type='fixed'>
                <parent>pan_motor</parent>
                <child>pan_support</child>
            </joint>
            
            <joint name='pan_support_joint' type='fixed'>
                <parent>pan_support</parent>
                <child>tilt_motor</child>
            </joint>
            
            <joint name='tilt_motor_joint' type='revolute'>
                <parent>pan_support</parent>
                <child>plate</child>
                <axis>
                    <xyz>1 0 0</xyz>
                    <limit>
                        <lower>-1e16</lower>
                        <upper>1e16</upper>
                        <effort>5e6</effort>
                    </limit>
                </axis>
            </joint>
            
            <plugin filename="gz-sim-joint-controller-system" name="gz::sim::systems::JointController">
                <joint_name>base_joint</joint_name>
                <topic>/pan/command</topic>
                <velocity_pid>
                    <p>1.0</p>
                    <i>0.0</i>
                    <d>0.0</d>
                    <reset_on_setpoint_change>true</reset_on_setpoint_change> 
                </velocity_pid>
            </plugin>
            
            <plugin filename="gz-sim-joint-controller-system" name="gz::sim::systems::JointController">
                <joint_name>tilt_motor_joint</joint_name>
                <topic>/tilt/command</topic>
                <velocity_pid>
                    <p>1.0</p>
                    <i>0.0</i>
                    <d>0.0</d>
                    <reset_on_setpoint_change>true</reset_on_setpoint_change> 
                </velocity_pid>
            </plugin>
        </model>
                
        <plugin filename="gz-sim-triggered-publisher-system"
                name="gz::sim::systems::TriggeredPublisher">
            <input type="gz.msgs.Int32" topic="/keyboard/keypress">
                <match field="data">16777235</match>  
            </input>
            <output type="gz.msgs.Double" topic="/tilt/command">
                data: 0.3  
            </output>
        </plugin>
        
        <plugin filename="gz-sim-triggered-publisher-system"
                 name="gz::sim::systems::TriggeredPublisher">
            <input type="gz.msgs.Int32" topic="/keyboard/keypress">
                <match field="data">16777237</match> 
            </input>
            <output type="gz.msgs.Double" topic="/tilt/command">
                data: -0.3  
            </output>
        </plugin>
        
        <plugin filename="gz-sim-triggered-publisher-system"
                name="gz::sim::systems::TriggeredPublisher">
            <input type="gz.msgs.Int32" topic="/keyboard/keypress">
                <match field="data">16777234</match> 
            </input>
            <output type="gz.msgs.Double" topic="/pan/command">
                data: 0.3 
            </output>
        </plugin>
        
        <plugin filename="gz-sim-triggered-publisher-system"
                name="gz::sim::systems::TriggeredPublisher">
            <input type="gz.msgs.Int32" topic="/keyboard/keypress">
                <match field="data">16777236</match> 
            </input>
            <output type="gz.msgs.Double" topic="/pan/command">
                data: -0.3  
            </output>
        </plugin>
</sdf>

